Workbook

Sheet Report Card
A1: ='FM-2'!$I$3 -> APS Hazro
A2: ='FM-2'!$J$3 -> ANNUAL EXAM 2024
A4: Name of Student: | C4: ='FM-2'!E3 -> Ali1 | F4: Father's Name: | H4: ='FM-2'!F3 -> Khan 1
A5: Admission No. | C5: ='FM-2'!C3 -> 1000 | D5: Class: | E5: ='FM-2'!$B$3 -> 7TH | F5: Examination Roll No. | H5: ='FM-2'!D3 -> 1
A6: Total students: | C6: =COUNTIF('Marks Input'!$B$4:$B$63,">0") -> 34
A7: Subjects | B7: Total Marks | C7: Marks Obtained | D7: %age | E7: Grade | F7: COMPARISON WITH CLASS
F8: Maximum Marks | G8: Minimum Marks | H8: Class Average | I8: Rank in Class
A9: ='Marks Input'!$G$2 -> Urdu | B9: ='Marks Input'!$G$3 -> 100 | C9: ='FM-2'!K3 -> 70 | D9: =C9/B9 -> 0.7 | E9: =IF(D9>0.899,"A+",IF(D9>0.799,"A",IF(D9>0.699,"B",IF(D9>0.599,"C",IF(D9>0.499,"D",IF(D9>0.399,"E","F")))))) -> B | F9: =MAX('Marks Input'!$G$4:$G$37) -> 72 | G9: =MIN('Marks Input'!$G$4:$G$37) -> 40 | H9: ='Marks Input'!$G$40 -> 62.59 | I9: ='FM-2'!V3 -> 3
A10: ='Marks Input'!$H$2 -> English | B10: ='Marks Input'!$H$3 -> 100 | C10: ='FM-2'!L3 -> 30 | D10: =C10/B10 -> 0.3 | E10: =IF(D10>0.899,"A+",IF(D10>0.799,"A",IF(D10>0.699,"B",IF(D10>0.599,"C",IF(D10>0.499,"D",IF(D10>0.399,"E","F")))))) -> F | F10: =MAX('Marks Input'!$H$4:$H$37) -> 74 | G10: =MIN('Marks Input'!$H$4:$H$37) -> 30 | H10: ='Marks Input'!$H$40 -> 43.26 | I10: ='FM-2'!W3 -> 34
A11: ='Marks Input'!$I$2 -> Islamiyat | B11: ='Marks Input'!$I$3 -> 100 | C11: ='FM-2'!M3 -> 37 | D11: =C11/B11 -> 0.37 | E11: =IF(D11>0.899,"A+",IF(D11>0.799,"A",IF(D11>0.699,"B",IF(D11>0.599,"C",IF(D11>0.499,"D",IF(D11>0.399,"E","F")))))) -> F | F11: =MAX('Marks Input'!$I$4:$I$37) -> 88 | G11: =MIN('Marks Input'!$I$4:$I$37) -> 34 | H11: ='Marks Input'!$I$40 -> 48.29 | I11: ='FM-2'!X3 -> 24
A12: ='Marks Input'!$J$2 -> Pak Studies | B12: ='Marks Input'!$J$3 -> 100 | C12: ='FM-2'!N3 -> 58 | D12: =C12/B12 -> 0.58 | E12: =IF(D12>0.899,"A+",IF(D12>0.799,"A",IF(D12>0.699,"B",IF(D12>0.599,"C",IF(D12>0.499,"D",IF(D12>0.399,"E","F")))))) -> D | F12: =MAX('Marks Input'!$J$4:$J$37) -> 96 | G12: =MIN('Marks Input'!$J$4:$J$37) -> 34 | H12: ='Marks Input'!$J$40 -> 71.03 | I12: ='FM-2'!Y3 -> 14
A13: ='Marks Input'!$K$2 -> Maths | B13: ='Marks Input'!$K$3 -> 100 | C13: ='FM-2'!O3 -> 40 | D13: =C13/B13 -> 0.4 | E13: =IF(D13>0.899,"A+",IF(D13>0.799,"A",IF(D13>0.699,"B",IF(D13>0.599,"C",IF(D13>0.499,"D",IF(D13>0.399,"E","F")))))) -> E | F13: =MAX('Marks Input'!$K$4:$K$37) -> 94 | G13: =MIN('Marks Input'!$K$4:$K$37) -> 57 | H13: ='Marks Input'!$K$40 -> 75.82 | I13: ='FM-2'!Z3 -> 19
A14: ='Marks Input'!$L$2 -> Sci./ Che. | B14: ='Marks Input'!$L$3 -> 100 | C14: ='FM-2'!P3 -> 70 | D14: =C14/B14 -> 0.7 | E14: =IF(D14>0.899,"A+",IF(D14>0.799,"A",IF(D14>0.699,"B",IF(D14>0.599,"C",IF(D14>0.499,"D",IF(D14>0.399,"E","F")))))) -> B | F14: =MAX('Marks Input'!$L$4:$L$37) -> 98 | G14: =MIN('Marks Input'!$L$4:$L$37) -> 40 | H14: ='Marks Input'!$L$40 -> 61.09 | I14: ='FM-2'!AA3 -> 19
A15: ='Marks Input'!$M$2 -> Nazra | B15: ='Marks Input'!$M$3 -> 100 | C15: ='FM-2'!Q3 -> 54 | D15: =C15/B15 -> 0.54 | E15: =IF(D15>0.899,"A+",IF(D15>0.799,"A",IF(D15>0.699,"B",IF(D15>0.599,"C",IF(D15>0.499,"D",IF(D15>0.399,"E","F")))))) -> D | F15: =MAX('Marks Input'!$M$4:$M$37) -> 94 | G15: =MIN('Marks Input'!$M$4:$M$37) -> 32 | H15: ='Marks Input'!$M$40 -> 57.79 | I15: ='FM-2'!AB3 -> 18
A16: ='Marks Input'!$N$2 -> Physics | B16: ='Marks Input'!$N$3 -> 100 | C16: ='FM-2'!R3 -> 83 | D16: =C16/B16 -> 0.83 | E16: =IF(D16>0.899,"A+",IF(D16>0.799,"A",IF(D16>0.699,"B",IF(D16>0.599,"C",IF(D16>0.499,"D",IF(D16>0.399,"E","F")))))) -> A | F16: =MAX('Marks Input'!$N$4:$N$37) -> 60 | G16: =MIN('Marks Input'!$N$4:$N$37) -> 18 | H16: ='Marks Input'!$N$40 -> 42.94 | I16: ='FM-2'!AC3 -> 7
A17: ='Marks Input'!$O$2 -> Bio./Comp. | B17: ='Marks Input'!$O$3 -> 100 | C17: ='FM-2'!S3 -> 54 | D17: =C17/B17 -> 0.54 | E17: =IF(D17>0.899,"A+",IF(D17>0.799,"A",IF(D17>0.699,"B",IF(D17>0.599,"C",IF(D17>0.499,"D",IF(D17>0.399,"E","F")))))) -> D | F17: =MAX('Marks Input'!$O$4:$O$37) -> 40 | G17: =MIN('Marks Input'!$O$4:$O$37) -> 14 | H17: ='Marks Input'!$O$40 -> 30.44 | I17: ='FM-2'!AD3 -> 18
A18: Overall | B18: ='Marks Input'!$P$3 -> 900 | C18: ='FM-2'!U3 -> 470 | D18: =C18/B18 -> 0.52222222 | E18: =IF(D18>0.899,"A+",IF(D18>0.799,"A",IF(D18>0.699,"B",IF(D18>0.599,"C",IF(D18>0.499,"D",IF(D18>0.399,"E","F")))))) -> D | F18: =MAX('Marks Input'!$P$4:$P$37) -> 673 | G18: =MIN('Marks Input'!$P$4:$P$37) -> 322 | H18: ='Marks Input'!$P$40 -> 493.26 | I18: ='FM-2'!AF3 -> 23
A19: Class Teacher Remarks:
A20: =IF(D18>0.399,"Promoted Successfully","Not Promoted") -> Promoted Successfully
D22: Signature of Incharge:
D23: Signature of Principal:
F24: =A1 -> APS Hazro
A27: Roll No. | B27: =H5 -> 1 | D27: Class: | E27: =E5 -> 7TH | F27: Grade: | G27: =E18 -> D
A28: Whatsapp: | E28: Mobile Phone: | G28: ='FM-2'!G3 -> 3005326707
A29: Home Address:
A32: Date: | B32: =TODAY() -> 46315 | D32: Signature of Guardian:
A33: This is computer gernerated student report copy, attestation not required.
A36: ='FM-2'!$I$3 -> APS Hazro
A37: ='FM-2'!$J$3 -> ANNUAL EXAM 2024
A39: Name of Student: | C39: ='FM-2'!E4 -> Ali2 | F39: Father's Name: | H39: ='FM-2'!F4 -> khan2
A40: Admission No. | C40: ='FM-2'!C4 -> 1001 | D40: Class: | E40: ='FM-2'!$B$3 -> 7TH | F40: Examination Roll No. | H40: ='FM-2'!D4 -> 2
A41: Total students: | C41: =COUNTIF('Marks Input'!$B$4:$B$63,">0") -> 34
A42: Subjects | B42: Total Marks | C42: Marks Obtained | D42: %age | E42: Grade | F42: COMPARISON WITH CLASS
F43: Maximum Marks | G43: Minimum Marks | H43: Class Average | I43: Rank in Class
A44: ='Marks Input'!$G$2 -> Urdu | B44: ='Marks Input'!$G$3 -> 100 | C44: ='FM-2'!K4 -> 68 | D44: =C44/B44 -> 0.68 | E44: =IF(D44>0.899,"A+",IF(D44>0.799,"A",IF(D44>0.699,"B",IF(D44>0.599,"C",IF(D44>0.499,"D",IF(D44>0.399,"E","F")))))) -> C | F44: =MAX('Marks Input'!$G$4:$G$37) -> 72 | G44: =MIN('Marks Input'!$G$4:$G$37) -> 40 | H44: ='Marks Input'!$G$40 -> 62.59 | I44: ='FM-2'!V4 -> 9
A45: ='Marks Input'!$H$2 -> English | B45: ='Marks Input'!$H$3 -> 100 | C45: ='FM-2'!L4 -> 59 | D45: =C45/B45 -> 0.59 | E45: =IF(D45>0.899,"A+",IF(D45>0.799,"A",IF(D45>0.699,"B",IF(D45>0.599,"C",IF(D45>0.499,"D",IF(D45>0.399,"E","F")))))) -> D | F45: =MAX('Marks Input'!$H$4:$H$37) -> 74 | G45: =MIN('Marks Input'!$H$4:$H$37) -> 30 | H45: ='Marks Input'!$H$40 -> 43.26 | I45: ='FM-2'!W4 -> 7
A46: ='Marks Input'!$I$2 -> Islamiyat | B46: ='Marks Input'!$I$3 -> 100 | C46: ='FM-2'!M4 -> 58 | D46: =C46/B46 -> 0.58 | E46: =IF(D46>0.899,"A+",IF(D46>0.799,"A",IF(D46>0.699,"B",IF(D46>0.599,"C",IF(D46>0.499,"D",IF(D46>0.399,"E","F")))))) -> D | F46: =MAX('Marks Input'!$I$4:$I$37) -> 88 | G46: =MIN('Marks Input'!$I$4:$I$37) -> 34 | H46: ='Marks Input'!$I$40 -> 48.29 | I46: ='FM-2'!X4 -> 5
A47: ='Marks Input'!$J$2 -> Pak Studies | B47: ='Marks Input'!$J$3 -> 100 | C47: ='FM-2'!N4 -> 56 | D47: =C47/B47 -> 0.56 | E47: =IF(D47>0.899,"A+",IF(D47>0.799,"A",IF(D47>0.699,"B",IF(D47>0.599,"C",IF(D47>0.499,"D",IF(D47>0.399,"E","F")))))) -> D | F47: =MAX('Marks Input'!$J$4:$J$37) -> 96 | G47: =MIN('Marks Input'!$J$4:$J$37) -> 34 | H47: ='Marks Input'!$J$40 -> 71.03 | I47: ='FM-2'!Y4 -> 17
A48: ='Marks Input'!$K$2 -> Maths | B48: ='Marks Input'!$K$3 -> 100 | C48: ='FM-2'!O4 -> 40 | D48: =C48/B48 -> 0.4 | E48: =IF(D48>0.899,"A+",IF(D48>0.799,"A",IF(D48>0.699,"B",IF(D48>0.599,"C",IF(D48>0.499,"D",IF(D48>0.399,"E","F")))))) -> E | F48: =MAX('Marks Input'!$K$4:$K$37) -> 94 | G48: =MIN('Marks Input'!$K$4:$K$37) -> 57 | H48: ='Marks Input'!$K$40 -> 75.82 | I48: ='FM-2'!Z4 -> 19
A49: ='Marks Input'!$L$2 -> Sci./ Che. | B49: ='Marks Input'!$L$3 -> 100 | C49: ='FM-2'!P4 -> 92 | D49: =C49/B49 -> 0.92 | E49: =IF(D49>0.899,"A+",IF(D49>0.799,"A",IF(D49>0.699,"B",IF(D49>0.599,"C",IF(D49>0.499,"D",IF(D49>0.399,"E","F")))))) -> A+ | F49: =MAX('Marks Input'!$L$4:$L$37) -> 98 | G49: =MIN('Marks Input'!$L$4:$L$37) -> 40 | H49: ='Marks Input'!$L$40 -> 61.09 | I49: ='FM-2'!AA4 -> 9
...

Sheet Student Information
A1: STUDENTS FAMILY INFORMATION
A3: CLASS | B3: Roll No. | C3: Admission No. | D3: Name | E3: How many brothers you have? | F3: How many sistes you have? | G3: What is your father's occupation? | H3: Home Address | I3: More Occupation Detail (if any) | J3: Monthly Income of your father (In digits) | K3: Optional Subject-1 | L3: Optional Subject-2 | M3: Optional Subject-3 | N3: No. of brothers /cousins attend this school | O3: One side distance of school from home in Kms: | P3: Mode of travelling to school: | Q3: In which shift you want to study: (Please tick one box) | R3: Which game you want to join? | V3: 1 | W3: Bicycle | X3: Basketball | Z3: Arabic
U4: Auto Electrician | V4: 2 | W4: Droped by family | X4: Cricket | Z4: Biology
U5: Auto Mechanic | V5: 3 | W5: Hired pick and drop | X5: Football | Z5: Chemistry
A6: ='Students Attendance'!A6 -> 7TH | B6: ='Students Attendance'!B6 -> 1 | C6: ='Students Attendance'!C6 -> 1000 | D6: ='Students Attendance'!D6 -> Ali1 | U6: Buisnessman | V6: 4 | W6: Motorcycle | X6: Hockey | Z6: Computer
A7: ='Students Attendance'!A7 -> 7TH | B7: ='Students Attendance'!B7 -> 2 | C7: ='Students Attendance'!C7 -> 1001 | D7: ='Students Attendance'!D7 -> Ali2 | U7: Carpenter | V7: 5 | W7: Public transport | X7: Volley Ball | Z7: Drawing
A8: ='Students Attendance'!A8 -> 7TH | B8: ='Students Attendance'!B8 -> 3 | C8: ='Students Attendance'!C8 -> 1002 | D8: ='Students Attendance'!D8 -> Ali3 | U8: Clerk | V8: 6 | W8: Walk | Z8: Electricity
A9: ='Students Attendance'!A9 -> 7TH | B9: ='Students Attendance'!B9 -> 4 | C9: ='Students Attendance'!C9 -> 1003 | D9: ='Students Attendance'!D9 -> Ali4 | U9: Doctor | V9: 7 | Z9: Metal Work
A10: ='Students Attendance'!A10 -> 7TH | B10: ='Students Attendance'!B10 -> 5 | C10: ='Students Attendance'!C10 -> 1004 | D10: ='Students Attendance'!D10 -> Ali5 | U10: Electrician | V10: 8 | Z10: Physics
A11: ='Students Attendance'!A11 -> 7TH | B11: ='Students Attendance'!B11 -> 6 | C11: ='Students Attendance'!C11 -> 1005 | D11: ='Students Attendance'!D11 -> Ali6 | U11: Engineer | V11: 9 | Z11: Wood Work
A12: ='Students Attendance'!A12 -> 7TH | B12: ='Students Attendance'!B12 -> 7 | C12: ='Students Attendance'!C12 -> 1006 | D12: ='Students Attendance'!D12 -> Ali7 | U12: Farmer | V12: 10
A13: ='Students Attendance'!A13 -> 7TH | B13: ='Students Attendance'!B13 -> 8 | C13: ='Students Attendance'!C13 -> 1007 | D13: ='Students Attendance'!D13 -> Ali8 | U13: Govt. Officer
A14: ='Students Attendance'!A14 -> 7TH | B14: ='Students Attendance'!B14 -> 9 | C14: ='Students Attendance'!C14 -> 1008 | D14: ='Students Attendance'!D14 -> Ali9 | U14: Industrialist
A15: ='Students Attendance'!A15 -> 7TH | B15: ='Students Attendance'!B15 -> 10 | C15: ='Students Attendance'!C15 -> 1009 | D15: ='Students Attendance'!D15 -> Ali10 | U15: Lobourer
A16: ='Students Attendance'!A16 -> 7TH | B16: ='Students Attendance'!B16 -> 11 | C16: ='Students Attendance'!C16 -> 1010 | D16: ='Students Attendance'!D16 -> Ali11 | U16: Machinest
A17: ='Students Attendance'!A17 -> 7TH | B17: ='Students Attendance'!B17 -> 12 | C17: ='Students Attendance'!C17 -> 1011 | D17: ='Students Attendance'!D17 -> Ali12 | U17: Manager
A18: ='Students Attendance'!A18 -> 7TH | B18: ='Students Attendance'!B18 -> 13 | C18: ='Students Attendance'!C18 -> 1012 | D18: ='Students Attendance'!D18 -> Ali13 | U18: Painter
A19: ='Students Attendance'!A19 -> 7TH | B19: ='Students Attendance'!B19 -> 14 | C19: ='Students Attendance'!C19 -> 1013 | D19: ='Students Attendance'!D19 -> Ali14 | U19: Police Officer
A20: ='Students Attendance'!A20 -> 7TH | B20: ='Students Attendance'!B20 -> 15 | C20: ='Students Attendance'!C20 -> 1014 | D20: ='Students Attendance'!D20 -> Ali15 | U20: Policeman
A21: ='Students Attendance'!A21 -> 7TH | B21: ='Students Attendance'!B21 -> 16 | C21: ='Students Attendance'!C21 -> 1015 | D21: ='Students Attendance'!D21 -> Ali16 | U21: Professor
A22: ='Students Attendance'!A22 -> 7TH | B22: ='Students Attendance'!B22 -> 17 | C22: ='Students Attendance'!C22 -> 1016 | D22: ='Students Attendance'!D22 -> Ali17 | U22: Shopkeeper
A23: ='Students Attendance'!A23 -> 7TH | B23: ='Students Attendance'!B23 -> 18 | C23: ='Students Attendance'!C23 -> 1017 | D23: ='Students Attendance'!D23 -> Ali18 | U23: Soldier
A24: ='Students Attendance'!A24 -> 7TH | B24: ='Students Attendance'!B24 -> 19 | C24: ='Students Attendance'!C24 -> 1018 | D24: ='Students Attendance'!D24 -> Ali19 | U24: Teacher
A25: ='Students Attendance'!A25 -> 7TH | B25: ='Students Attendance'!B25 -> 20 | C25: ='Students Attendance'!C25 -> 1019 | D25: ='Students Attendance'!D25 -> Ali20 | U25: Welder
A26: ='Students Attendance'!A26 -> 7TH | B26: ='Students Attendance'!B26 -> 21 | C26: ='Students Attendance'!C26 -> 1020 | D26: ='Students Attendance'!D26 -> Ali21
A27: ='Students Attendance'!A27 -> 7TH | B27: ='Students Attendance'!B27 -> 22 | C27: ='Students Attendance'!C27 -> 1021 | D27: ='Students Attendance'!D27 -> Ali22
A28: ='Students Attendance'!A28 -> 7TH | B28: ='Students Attendance'!B28 -> 23 | C28: ='Students Attendance'!C28 -> 1022 | D28: ='Students Attendance'!D28 -> Ali23
A29: ='Students Attendance'!A29 -> 7TH | B29: ='Students Attendance'!B29 -> 24 | C29: ='Students Attendance'!C29 -> 1023 | D29: ='Students Attendance'!D29 -> Ali24
A30: ='Students Attendance'!A30 -> 7TH | B30: ='Students Attendance'!B30 -> 25 | C30: ='Students Attendance'!C30 -> 1024 | D30: ='Students Attendance'!D30 -> Ali25
A31: ='Students Attendance'!A31 -> 7TH | B31: ='Students Attendance'!B31 -> 26 | C31: ='Students Attendance'!C31 -> 1025 | D31: ='Students Attendance'!D31 -> Ali26
A32: ='Students Attendance'!A32 -> 7TH | B32: ='Students Attendance'!B32 -> 27 | C32: ='Students Attendance'!C32 -> 1026 | D32: ='Students Attendance'!D32 -> Ali27
A33: ='Students Attendance'!A33 -> 7TH | B33: ='Students Attendance'!B33 -> 28 | C33: ='Students Attendance'!C33 -> 1027 | D33: ='Students Attendance'!D33 -> Ali28
A34: ='Students Attendance'!A34 -> 7TH | B34: ='Students Attendance'!B34 -> 29 | C34: ='Students Attendance'!C34 -> 1028 | D34: ='Students Attendance'!D34 -> Ali29
A35: ='Students Attendance'!A35 -> 7TH | B35: ='Students Attendance'!B35 -> 30 | C35: ='Students Attendance'!C35 -> 1029 | D35: ='Students Attendance'!D35 -> Ali30
A36: ='Students Attendance'!A36 -> 7TH | B36: ='Students Attendance'!B36 -> 31 | C36: ='Students Attendance'!C36 -> 1030 | D36: ='Students Attendance'!D36 -> Ali31
A37: ='Students Attendance'!A37 -> 7TH | B37: ='Students Attendance'!B37 -> 32 | C37: ='Students Attendance'!C37 -> 1031 | D37: ='Students Attendance'!D37 -> Ali32
... A39: ='Students Attendance'!A39 -> 7TH | B39: ='Students Attendance'!B39 -> 34 | C39: ='Students Attendance'!C39 -> 1033 | D39: ='Students Attendance'!D39 -> Ali34

Sheet Marks Input
A1: Student Information | F1: Marks Obtained clr
A2: Sr.No. | B2: Admission No. | C2: Class | D2: Roll No. | E2: Name of Student | F2: Name of Exam | G2: Urdu | H2: English | I2: Islamiyat | J2: Pak Studies | K2: Maths | L2: Sci./ Che. | M2: Nazra | N2: Physics | O2: Bio./Comp. | P2: Total
A3: Total Marks => | G3: 100 | H3: 100 | I3: 100 | J3: 100 | K3: 100 | L3: 100 | M3: 100 | N3: 100 | O3: 100 | P3: =SUM(G3,H3,I3,J3,K3,L3,M3,N3,O3) -> 900
A4: 1 | B4: ='FM-1'!D3 -> 1000 | C4: ='FM-1'!B3 -> 7TH | D4: ='FM-1'!C3 -> 1 | E4: ='FM-1'!E3 -> Ali1 | F4: ANNUAL EXAM 2024 | G4: 70 | H4: 30 | I4: 40 | J4: 70 | K4: 83 | L4: 58 | M4: 54 | N4: 37 | O4: 28 | P4: =SUM(G4,H4,I4,J4,K4,L4,M4,N4,O4) -> 470
A5: 2 | B5: ='FM-1'!D4 -> 1001 | C5: ='FM-1'!B4 -> 7TH | D5: ='FM-1'!C4 -> 2 | E5: ='FM-1'!E4 -> Ali2 | F5: =F4 -> ANNUAL EXAM 2024 | G5: 68 | H5: 59 | I5: 40 | J5: 92 | K5: 76 | L5: 56 | M5: 61 | N5: 58 | O5: 40 | P5: =SUM(G5,H5,I5,J5,K5,L5,M5,N5,O5) -> 550
A6: 3 | B6: ='FM-1'!D5 -> 1002 | C6: ='FM-1'!B5 -> 7TH | D6: ='FM-1'!C5 -> 3 | E6: ='FM-1'!E5 -> Ali3 | F6: =F5 -> ANNUAL EXAM 2024 | G6: 68 | H6: 35 | I6: 34 | J6: 90 | K6: 77 | L6: 74 | M6: 61 | N6: 58 | O6: 37 | P6: =SUM(G6,H6,I6,J6,K6,L6,M6,N6,O6) -> 534
A7: 4 | B7: ='FM-1'!D6 -> 1003 | C7: ='FM-1'!B6 -> 7TH | D7: ='FM-1'!C6 -> 4 | E7: ='FM-1'!E6 -> Ali4 | F7: =F6 -> ANNUAL EXAM 2024 | G7: 64 | H7: 39 | I7: 40 | J7: 53 | K7: 80 | L7: 40 | M7: 45 | N7: 31 | O7: 21 | P7: =SUM(G7,H7,I7,J7,K7,L7,M7,N7,O7) -> 413
A8: 5 | B8: ='FM-1'!D7 -> 1004 | C8: ='FM-1'!B7 -> 7TH | D8: ='FM-1'!C7 -> 5 | E8: ='FM-1'!E7 -> Ali5 | F8: =F7 -> ANNUAL EXAM 2024 | G8: 63 | H8: 53 | I8: 88 | J8: 96 | K8: 75 | L8: 54 | M8: 58 | N8: 55 | O8: 40 | P8: =SUM(G8,H8,I8,J8,K8,L8,M8,N8,O8) -> 582
A9: 6 | B9: ='FM-1'!D8 -> 1005 | C9: ='FM-1'!B8 -> 7TH | D9: ='FM-1'!C8 -> 6 | E9: ='FM-1'!E8 -> Ali6 | F9: =F8 -> ANNUAL EXAM 2024 | G9: 63 | H9: 62 | I9: 60 | J9: 82 | K9: 78 | L9: 54 | M9: 53 | N9: 52 | O9: 32 | P9: =SUM(G9,H9,I9,J9,K9,L9,M9,N9,O9) -> 536
A10: 7 | B10: ='FM-1'!D9 -> 1006 | C10: ='FM-1'!B9 -> 7TH | D10: ='FM-1'!C9 -> 7 | E10: ='FM-1'!E9 -> Ali7 | F10: =F9 -> ANNUAL EXAM 2024 | G10: 64 | H10: 45 | I10: 40 | J10: 50 | K10: 74 | L10: 78 | M10: 53 | N10: 57 | O10: 36 | P10: =SUM(G10,H10,I10,J10,K10,L10,M10,N10,O10) -> 497
A11: 8 | B11: ='FM-1'!D10 -> 1007 | C11: ='FM-1'!B10 -> 7TH | D11: ='FM-1'!C10 -> 8 | E11: ='FM-1'!E10 -> Ali8 | F11: =F10 -> ANNUAL EXAM 2024 | G11: 69 | H11: 33 | I11: 50 | J11: 83 | K11: 93 | L11: 48 | M11: 73 | N11: 60 | O11: 39 | P11: =SUM(G11,H11,I11,J11,K11,L11,M11,N11,O11) -> 548
A12: 9 | B12: ='FM-1'!D11 -> 1008 | C12: ='FM-1'!B11 -> 7TH | D12: ='FM-1'!C11 -> 9 | E12: ='FM-1'!E11 -> Ali9 | F12: =F11 -> ANNUAL EXAM 2024 | G12: 65 | H12: 33 | I12: 44 | J12: 40 | K12: 73 | L12: 42 | M12: 43 | N12: 20 | O12: 15 | P12: =SUM(G12,H12,I12,J12,K12,L12,M12,N12,O12) -> 375
A13: 10 | B13: ='FM-1'!D12 -> 1009 | C13: ='FM-1'!B12 -> 7TH | D13: ='FM-1'!C12 -> 10 | E13: ='FM-1'!E12 -> Ali10 | F13: =F12 -> ANNUAL EXAM 2024 | G13: 49 | H13: 33 | I13: 40 | J13: 35 | K13: 60 | L13: 40 | M13: 37 | N13: 19 | O13: 15 | P13: =SUM(G13,H13,I13,J13,K13,L13,M13,N13,O13) -> 328
A14: 11 | B14: ='FM-1'!D13 -> 1010 | C14: ='FM-1'!B13 -> 7TH | D14: ='FM-1'!C13 -> 11 | E14: ='FM-1'!E13 -> Ali11 | F14: =F13 -> ANNUAL EXAM 2024 | G14: 40 | H14: 33 | I14: 40 | J14: 50 | K14: 62 | L14: 56 | M14: 49 | N14: 20 | O14: 15 | P14: =SUM(G14,H14,I14,J14,K14,L14,M14,N14,O14) -> 365
A15: 12 | B15: ='FM-1'!D14 -> 1011 | C15: ='FM-1'!B14 -> 7TH | D15: ='FM-1'!C14 -> 12 | E15: ='FM-1'!E14 -> Ali12 | F15: =F14 -> ANNUAL EXAM 2024 | G15: 54 | H15: 33 | I15: 36 | J15: 35 | K15: 57 | L15: 40 | M15: 35 | N15: 18 | O15: 14 | P15: =SUM(G15,H15,I15,J15,K15,L15,M15,N15,O15) -> 322
A16: 13 | B16: ='FM-1'!D15 -> 1012 | C16: ='FM-1'!B15 -> 7TH | D16: ='FM-1'!C15 -> 13 | E16: ='FM-1'!E15 -> Ali13 | F16: =F15 -> ANNUAL EXAM 2024 | G16: 68 | H16: 33 | I16: 40 | J16: 54 | K16: 67 | L16: 66 | M16: 43 | N16: 40 | O16: 28 | P16: =SUM(G16,H16,I16,J16,K16,L16,M16,N16,O16) -> 439
... A37: 34 | B37: ='FM-1'!D36 -> 1033 | C37: ='FM-1'!B36 -> 7TH | D37: ='FM-1'!C36 -> 34 | E37: ='FM-1'!E36 -> Ali34 | F37: =F36 -> ANNUAL EXAM 2024 | G37: 72 | H37: 58 | I37: 76 | J37: 95 | K37: 84 | L37: 90 | M37: 61 | N37: 57 | O37: 40 | P37: =SUM(G37,H37,I37,J37,K37,L37,M37,N37,O37) -> 633
A38: 35 | B38: ='FM-1'!#REF! -> #REF! | C38: ='FM-1'!#REF! -> #REF! | F38: SUM | G38: =SUMIF(G$4:G$37,">-1") -> 2128 | H38: =SUMIF(H$4:H$37,">-1") -> 1471 | I38: =SUMIF(I$4:I$37,">-1") -> 1642 | J38: =SUMIF(J$4:J$37,">-1") -> 2415 | K38: =SUMIF(K$4:K$37,">-1") -> 2578 | L38: =SUMIF(L$4:L$37,">-1") -> 2077 | M38: =SUMIF(M$4:M$37,">-1") -> 1965 | N38: =SUMIF(N$4:N$37,">-1") -> 1460 | ... P38: =SUMIF(P$4:P$37,">-1") -> 16771
A39: 36 | B39: ='FM-1'!#REF! -> #REF! | C39: ='FM-1'!#REF! -> #REF! | F39: Student Count | G39: =COUNTIF($D$4:$D37,">0") -> 34 | H39: =COUNTIF($D$4:$D37,">0") -> 34 | I39: =COUNTIF($D$4:$D37,">0") -> 34 | J39: =COUNTIF($D$4:$D37,">0") -> 34 | K39: =COUNTIF($D$4:$D37,">0") -> 34 | L39: =COUNTIF($D$4:$D37,">0") -> 34 | M39: =COUNTIF($D$4:$D37,">0") -> 34 | N39: =COUNTIF($D$4:$D37,">0") -> 34 | ... P39: =COUNTIF($D$4:$D37,">0") -> 34
A40: 37 | B40: ='FM-1'!#REF! -> #REF! | C40: ='FM-1'!#REF! -> #REF! | F40: Average | G40: =ROUND(G38/G39,2) -> 62.59 | H40: =ROUND(H38/H39,2) -> 43.26 | I40: =ROUND(I38/I39,2) -> 48.29 | J40: =ROUND(J38/J39,2) -> 71.03 | K40: =ROUND(K38/K39,2) -> 75.82 | L40: =ROUND(L38/L39,2) -> 61.09 | M40: =ROUND(M38/M39,2) -> 57.79 | N40: =ROUND(N38/N39,2) -> 42.94 | ... P40: =ROUND(P38/P39,2) -> 493.26
A41: 38 | B41: ='FM-1'!#REF! -> #REF! | C41: ='FM-1'!#REF! -> #REF!
A42: 39 | B42: ='FM-1'!#REF! -> #REF! | C42: ='FM-1'!#REF! -> #REF!
A43: 40 | B43: ='FM-1'!#REF! -> #REF! | C43: ='FM-1'!#REF! -> #REF!
A44: 41 | B44: ='FM-1'!#REF! -> #REF! | C44: ='FM-1'!#REF! -> #REF!
A45: 42 | B45: ='FM-1'!#REF! -> #REF! | C45: ='FM-1'!#REF! -> #REF!
A46: 43 | B46: ='FM-1'!#REF! -> #REF! | C46: ='FM-1'!#REF! -> #REF!
A47: 44 | B47: ='FM-1'!#REF! -> #REF! | C47: ='FM-1'!#REF! -> #REF!
A48: 45 | B48: ='FM-1'!#REF! -> #REF! | C48: ='FM-1'!#REF! -> #REF!
A49: 46 | B49: ='FM-1'!#REF! -> #REF! | C49: ='FM-1'!#REF! -> #REF!
A50: 47 | B50: ='FM-1'!#REF! -> #REF! | C50: ='FM-1'!#REF! -> #REF!
A51: 48 | B51: ='FM-1'!#REF! -> #REF! | C51: ='FM-1'!#REF! -> #REF!
A52: 49 | B52: ='FM-1'!#REF! -> #REF! | C52: ='FM-1'!#REF! -> #REF!
... A63: 60 | B63: ='FM-1'!#REF! -> #REF! | C63: ='FM-1'!#REF! -> #REF!

Sheet FM-1
A1: Students Information clr
A2: Sr.No. | B2: Class | C2: Roll No. | D2: Admission No. | E2: Name of Student | F2: Father's Name | G2: Contact Number | H2: Home Address | I2: Name of School
A3: 1 | B3: ='Students Attendance'!$H$2 -> 7TH | C3: ='Students Attendance'!B6 -> 1 | D3: ='Students Attendance'!C6 -> 1000 | E3: ='Students Attendance'!D6 -> Ali1 | F3: ='Students Attendance'!F6 -> Khan 1 | G3: ='Students Attendance'!H6 -> 3005326707 | H3: ='Students Attendance'!I6 -> 0 | I3: ='Students Attendance'!$F$1 -> APS Hazro
A4: 2 | B4: ='Students Attendance'!$H$2 -> 7TH | C4: ='Students Attendance'!B7 -> 2 | D4: ='Students Attendance'!C7 -> 1001 | E4: ='Students Attendance'!D7 -> Ali2 | F4: ='Students Attendance'!F7 -> khan2 | G4: ='Students Attendance'!H7 -> 3005326748 | H4: ='Students Attendance'!I7 -> 0 | I4: ='Students Attendance'!$F$1 -> APS Hazro
A5: 3 | B5: ='Students Attendance'!$H$2 -> 7TH | C5: ='Students Attendance'!B8 -> 3 | D5: ='Students Attendance'!C8 -> 1002 | E5: ='Students Attendance'!D8 -> Ali3 | F5: ='Students Attendance'!F8 -> khan3 | G5: ='Students Attendance'!H8 -> 3005326789 | H5: ='Students Attendance'!I8 -> 0 | I5: ='Students Attendance'!$F$1 -> APS Hazro
A6: 4 | B6: ='Students Attendance'!$H$2 -> 7TH | C6: ='Students Attendance'!B9 -> 4 | D6: ='Students Attendance'!C9 -> 1003 | E6: ='Students Attendance'!D9 -> Ali4 | F6: ='Students Attendance'!F9 -> Khan 4 | G6: ='Students Attendance'!H9 -> 3005326830 | H6: ='Students Attendance'!I9 -> 0 | I6: ='Students Attendance'!$F$1 -> APS Hazro
A7: 5 | B7: ='Students Attendance'!$H$2 -> 7TH | C7: ='Students Attendance'!B10 -> 5 | D7: ='Students Attendance'!C10 -> 1004 | E7: ='Students Attendance'!D10 -> Ali5 | F7: ='Students Attendance'!F10 -> Khan 5 | G7: ='Students Attendance'!H10 -> 3005326871 | H7: ='Students Attendance'!I10 -> 0 | I7: ='Students Attendance'!$F$1 -> APS Hazro
A8: 6 | B8: ='Students Attendance'!$H$2 -> 7TH | C8: ='Students Attendance'!B11 -> 6 | D8: ='Students Attendance'!C11 -> 1005 | E8: ='Students Attendance'!D11 -> Ali6 | F8: ='Students Attendance'!F11 -> Khan 6 | G8: ='Students Attendance'!H11 -> 3005326912 | H8: ='Students Attendance'!I11 -> 0 | I8: ='Students Attendance'!$F$1 -> APS Hazro
A9: 7 | B9: ='Students Attendance'!$H$2 -> 7TH | C9: ='Students Attendance'!B12 -> 7 | D9: ='Students Attendance'!C12 -> 1006 | E9: ='Students Attendance'!D12 -> Ali7 | F9: ='Students Attendance'!F12 -> Khan 7 | G9: ='Students Attendance'!H12 -> 3005326953 | H9: ='Students Attendance'!I12 -> 0 | I9: ='Students Attendance'!$F$1 -> APS Hazro
A10: 8 | B10: ='Students Attendance'!$H$2 -> 7TH | C10: ='Students Attendance'!B13 -> 8 | D10: ='Students Attendance'!C13 -> 1007 | E10: ='Students Attendance'!D13 -> Ali8 | F10: ='Students Attendance'!F13 -> Khan 8 | G10: ='Students Attendance'!H13 -> 3005326994 | H10: ='Students Attendance'!I13 -> 0 | I10: ='Students Attendance'!$F$1 -> APS Hazro
A11: 9 | B11: ='Students Attendance'!$H$2 -> 7TH | C11: ='Students Attendance'!B14 -> 9 | D11: ='Students Attendance'!C14 -> 1008 | E11: ='Students Attendance'!D14 -> Ali9 | F11: ='Students Attendance'!F14 -> Khan 9 | G11: ='Students Attendance'!H14 -> 3005327035 | H11: ='Students Attendance'!I14 -> 0 | I11: ='Students Attendance'!$F$1 -> APS Hazro
A12: 10 | B12: ='Students Attendance'!$H$2 -> 7TH | C12: ='Students Attendance'!B15 -> 10 | D12: ='Students Attendance'!C15 -> 1009 | E12: ='Students Attendance'!D15 -> Ali10 | F12: ='Students Attendance'!F15 -> Khan 10 | G12: ='Students Attendance'!H15 -> 3005327076 | H12: ='Students Attendance'!I15 -> 0 | I12: ='Students Attendance'!$F$1 -> APS Hazro
A13: 11 | B13: ='Students Attendance'!$H$2 -> 7TH | C13: ='Students Attendance'!B16 -> 11 | D13: ='Students Attendance'!C16 -> 1010 | E13: ='Students Attendance'!D16 -> Ali11 | F13: ='Students Attendance'!F16 -> Khan 11 | G13: ='Students Attendance'!H16 -> 3005327117 | H13: ='Students Attendance'!I16 -> 0 | I13: ='Students Attendance'!$F$1 -> APS Hazro
A14: 12 | B14: ='Students Attendance'!$H$2 -> 7TH | C14: ='Students Attendance'!B17 -> 12 | D14: ='Students Attendance'!C17 -> 1011 | E14: ='Students Attendance'!D17 -> Ali12 | F14: ='Students Attendance'!F17 -> Khan 12 | G14: ='Students Attendance'!H17 -> 3005327158 | H14: ='Students Attendance'!I17 -> 0 | I14: ='Students Attendance'!$F$1 -> APS Hazro
... A36: 34 | B36: ='Students Attendance'!$H$2 -> 7TH | C36: ='Students Attendance'!B39 -> 34 | D36: ='Students Attendance'!C39 -> 1033 | E36: ='Students Attendance'!D39 -> Ali34 | F36: ='Students Attendance'!F39 -> Khan 34 | G36: ='Students Attendance'!H39 -> 3005328060 | H36: ='Students Attendance'!I39 -> 0 | I36: ='Students Attendance'!$F$1 -> APS Hazro

Sheet FM-2
A1: Student Information | J1: Obtained Marks | V1: Position in Class
A2: Sr. No. | B2: Class | C2: Admission No. | D2: Roll No. | E2: Name of Student | F2: Father's Name | G2: Contact | H2: Home Address | I2: Name of School | J2: Name of Exam | K2: Urdu | L2: English | M2: Islamiyat | N2: Pakistan Studies | O2: Maths | P2: Sci./Chemistry | Q2: Nazra | R2: Physics | S2: Bio./Computer | T2: Attendance | U2: Total | V2: Urdu | W2: English | X2: Islamiyat | Y2: Pakistan Studies | Z2: Maths | AA2: Sci./Chemistry | AB2: Nazra | AC2: Physics | AD2: Bio./Computer | AE2: Attendance | AF2: Total
A3: ='FM-1'!A3 -> 1 | B3: ='FM-1'!B3 -> 7TH | C3: ='FM-1'!D3 -> 1000 | D3: ='FM-1'!C3 -> 1 | E3: ='FM-1'!E3 -> Ali1 | F3: ='FM-1'!F3 -> Khan 1 | G3: ='FM-1'!G3 -> 3005326707 | H3: ='FM-1'!H3 -> 0 | I3: ='FM-1'!I3 -> APS Hazro | J3: ='Marks Input'!F4 -> ANNUAL EXAM 2024 | K3: ='Marks Input'!G4 -> 70 | L3: ='Marks Input'!H4 -> 30 | M3: ='Marks Input'!N4 -> 37 | N3: ='Marks Input'!L4 -> 58 | O3: ='Marks Input'!I4 -> 40 | P3: ='Marks Input'!J4 -> 70 | Q3: ='Marks Input'!M4 -> 54 | R3: ='Marks Input'!K4 -> 83 | S3: ='Marks Input'!M4 -> 54 | T3: 11 | U3: ='Marks Input'!P4 -> 470 | V3: =RANK(K3,K$3:K$38,0) -> 3 | W3: =RANK(L3,L$3:L$38,0) -> 34 | X3: =RANK(M3,M$3:M$38,0) -> 24 | Y3: =RANK(N3,N$3:N$38,0) -> 14 | Z3: =RANK(O3,O$3:O$38,0) -> 19 | AA3: =RANK(P3,P$3:P$38,0) -> 19 | AB3: =RANK(Q3,Q$3:Q$38,0) -> 18 | AC3: =RANK(R3,R$3:R$38,0) -> 7 | AD3: =RANK(S3,S$3:S$38,0) -> 18 | AF3: =RANK(U3,U$3:U$38,0) -> 23
A4: ='FM-1'!A4 -> 2 | B4: ='FM-1'!B4 -> 7TH | C4: ='FM-1'!D4 -> 1001 | D4: ='FM-1'!C4 -> 2 | E4: ='FM-1'!E4 -> Ali2 | F4: ='FM-1'!F4 -> khan2 | G4: ='FM-1'!G4 -> 3005326748 | H4: ='FM-1'!H4 -> 0 | I4: ='FM-1'!I4 -> APS Hazro | J4: ='Marks Input'!F5 -> ANNUAL EXAM 2024 | K4: ='Marks Input'!G5 -> 68 | L4: ='Marks Input'!H5 -> 59 | M4: ='Marks Input'!N5 -> 58 | N4: ='Marks Input'!L5 -> 56 | O4: ='Marks Input'!I5 -> 40 | P4: ='Marks Input'!J5 -> 92 | Q4: ='Marks Input'!M5 -> 61 | R4: ='Marks Input'!K5 -> 76 | S4: ='Marks Input'!M5 -> 61 | T4: 11 | U4: ='Marks Input'!P5 -> 550 | V4: =RANK(K4,K$3:K$38,0) -> 9 | W4: =RANK(L4,L$3:L$38,0) -> 7 | X4: =RANK(M4,M$3:M$38,0) -> 5 | Y4: =RANK(N4,N$3:N$38,0) -> 17 | Z4: =RANK(O4,O$3:O$38,0) -> 19 | AA4: =RANK(P4,P$3:P$38,0) -> 9 | AB4: =RANK(Q4,Q$3:Q$38,0) -> 10 | AC4: =RANK(R4,R$3:R$38,0) -> 14 | AD4: =RANK(S4,S$3:S$38,0) -> 10 | AF4: =RANK(U4,U$3:U$38,0) -> 9
A5: ='FM-1'!A5 -> 3 | B5: ='FM-1'!B5 -> 7TH | C5: ='FM-1'!D5 -> 1002 | D5: ='FM-1'!C5 -> 3 | E5: ='FM-1'!E5 -> Ali3 | F5: ='FM-1'!F5 -> khan3 | G5: ='FM-1'!G5 -> 3005326789 | H5: ='FM-1'!H5 -> 0 | I5: ='FM-1'!I5 -> APS Hazro | J5: ='Marks Input'!F6 -> ANNUAL EXAM 2024 | K5: ='Marks Input'!G6 -> 68 | L5: ='Marks Input'!H6 -> 35 | M5: ='Marks Input'!N6 -> 58 | N5: ='Marks Input'!L6 -> 74 | O5: ='Marks Input'!I6 -> 34 | P5: ='Marks Input'!J6 -> 90 | Q5: ='Marks Input'!M6 -> 61 | R5: ='Marks Input'!K6 -> 77 | S5: ='Marks Input'!M6 -> 61 | T5: 11 | U5: ='Marks Input'!P6 -> 534 | V5: =RANK(K5,K$3:K$38,0) -> 9 | W5: =RANK(L5,L$3:L$38,0) -> 18 | X5: =RANK(M5,M$3:M$38,0) -> 5 | Y5: =RANK(N5,N$3:N$38,0) -> 10 | Z5: =RANK(O5,O$3:O$38,0) -> 31 | AA5: =RANK(P5,P$3:P$38,0) -> 10 | AB5: =RANK(Q5,Q$3:Q$38,0) -> 10 | AC5: =RANK(R5,R$3:R$38,0) -> 11 | AD5: =RANK(S5,S$3:S$38,0) -> 10 | AF5: =RANK(U5,U$3:U$38,0) -> 13
A6: ='FM-1'!A6 -> 4 | B6: ='FM-1'!B6 -> 7TH | C6: ='FM-1'!D6 -> 1003 | D6: ='FM-1'!C6 -> 4 | E6: ='FM-1'!E6 -> Ali4 | F6: ='FM-1'!F6 -> Khan 4 | G6: ='FM-1'!G6 -> 3005326830 | H6: ='FM-1'!H6 -> 0 | I6: ='FM-1'!I6 -> APS Hazro | J6: ='Marks Input'!F7 -> ANNUAL EXAM 2024 | K6: ='Marks Input'!G7 -> 64 | L6: ='Marks Input'!H7 -> 39 | M6: ='Marks Input'!N7 -> 31 | N6: ='Marks Input'!L7 -> 40 | O6: ='Marks Input'!I7 -> 40 | P6: ='Marks Input'!J7 -> 53 | Q6: ='Marks Input'!M7 -> 45 | R6: ='Marks Input'!K7 -> 80 | S6: ='Marks Input'!M7 -> 45 | T6: 11 | U6: ='Marks Input'!P7 -> 413 | V6: =RANK(K6,K$3:K$38,0) -> 18 | W6: =RANK(L6,L$3:L$38,0) -> 17 | X6: =RANK(M6,M$3:M$38,0) -> 26 | Y6: =RANK(N6,N$3:N$38,0) -> 31 | Z6: =RANK(O6,O$3:O$38,0) -> 19 | AA6: =RANK(P6,P$3:P$38,0) -> 25 | AB6: =RANK(Q6,Q$3:Q$38,0) -> 26 | AC6: =RANK(R6,R$3:R$38,0) -> 8 | AD6: =RANK(S6,S$3:S$38,0) -> 26 | AF6: =RANK(U6,U$3:U$38,0) -> 26
A7: ='FM-1'!A7 -> 5 | B7: ='FM-1'!B7 -> 7TH | C7: ='FM-1'!D7 -> 1004 | D7: ='FM-1'!C7 -> 5 | E7: ='FM-1'!E7 -> Ali5 | F7: ='FM-1'!F7 -> Khan 5 | G7: ='FM-1'!G7 -> 3005326871 | H7: ='FM-1'!H7 -> 0 | I7: ='FM-1'!I7 -> APS Hazro | J7: ='Marks Input'!F8 -> ANNUAL EXAM 2024 | K7: ='Marks Input'!G8 -> 63 | L7: ='Marks Input'!H8 -> 53 | M7: ='Marks Input'!N8 -> 55 | N7: ='Marks Input'!L8 -> 54 | O7: ='Marks Input'!I8 -> 88 | P7: ='Marks Input'!J8 -> 96 | Q7: ='Marks Input'!M8 -> 58 | R7: ='Marks Input'!K8 -> 75 | S7: ='Marks Input'!M8 -> 58 | T7: 11 | U7: ='Marks Input'!P8 -> 582 | V7: =RANK(K7,K$3:K$38,0) -> 22 | W7: =RANK(L7,L$3:L$38,0) -> 9 | X7: =RANK(M7,M$3:M$38,0) -> 10 | Y7: =RANK(N7,N$3:N$38,0) -> 19 | Z7: =RANK(O7,O$3:O$38,0) -> 1 | AA7: =RANK(P7,P$3:P$38,0) -> 1 | AB7: =RANK(Q7,Q$3:Q$38,0) -> 15 | AC7: =RANK(R7,R$3:R$38,0) -> 16 | AD7: =RANK(S7,S$3:S$38,0) -> 15 | AF7: =RANK(U7,U$3:U$38,0) -> 6
A8: ='FM-1'!A8 -> 6 | B8: ='FM-1'!B8 -> 7TH | C8: ='FM-1'!D8 -> 1005 | D8: ='FM-1'!C8 -> 6 | E8: ='FM-1'!E8 -> Ali6 | F8: ='FM-1'!F8 -> Khan 6 | G8: ='FM-1'!G8 -> 3005326912 | H8: ='FM-1'!H8 -> 0 | I8: ='FM-1'!I8 -> APS Hazro | J8: ='Marks Input'!F9 -> ANNUAL EXAM 2024 | K8: ='Marks Input'!G9 -> 63 | L8: ='Marks Input'!H9 -> 62 | M8: ='Marks Input'!N9 -> 52 | N8: ='Marks Input'!L9 -> 54 | O8: ='Marks Input'!I9 -> 60 | P8: ='Marks Input'!J9 -> 82 | Q8: ='Marks Input'!M9 -> 53 | R8: ='Marks Input'!K9 -> 78 | S8: ='Marks Input'!M9 -> 53 | T8: 11 | U8: ='Marks Input'!P9 -> 536 | V8: =RANK(K8,K$3:K$38,0) -> 22 | W8: =RANK(L8,L$3:L$38,0) -> 4 | X8: =RANK(M8,M$3:M$38,0) -> 12 | Y8: =RANK(N8,N$3:N$38,0) -> 19 | Z8: =RANK(O8,O$3:O$38,0) -> 4 | AA8: =RANK(P8,P$3:P$38,0) -> 14 | AB8: =RANK(Q8,Q$3:Q$38,0) -> 20 | AC8: =RANK(R8,R$3:R$38,0) -> 9 | AD8: =RANK(S8,S$3:S$38,0) -> 20 | AF8: =RANK(U8,U$3:U$38,0) -> 12
A9: ='FM-1'!A9 -> 7 | B9: ='FM-1'!B9 -> 7TH | C9: ='FM-1'!D9 -> 1006 | D9: ='FM-1'!C9 -> 7 | E9: ='FM-1'!E9 -> Ali7 | F9: ='FM-1'!F9 -> Khan 7 | G9: ='FM-1'!G9 -> 3005326953 | H9: ='FM-1'!H9 -> 0 | I9: ='FM-1'!I9 -> APS Hazro | J9: ='Marks Input'!F10 -> ANNUAL EXAM 2024 | K9: ='Marks Input'!G10 -> 64 | L9: ='Marks Input'!H10 -> 45 | M9: ='Marks Input'!N10 -> 57 | N9: ='Marks Input'!L10 -> 78 | O9: ='Marks Input'!I10 -> 40 | P9: ='Marks Input'!J10 -> 50 | Q9: ='Marks Input'!M10 -> 53 | R9: ='Marks Input'!K10 -> 74 | S9: ='Marks Input'!M10 -> 53 | T9: 11 | U9: ='Marks Input'!P10 -> 497 | V9: =RANK(K9,K$3:K$38,0) -> 18 | W9: =RANK(L9,L$3:L$38,0) -> 12 | X9: =RANK(M9,M$3:M$38,0) -> 8 | Y9: =RANK(N9,N$3:N$38,0) -> 7 | Z9: =RANK(O9,O$3:O$38,0) -> 19 | AA9: =RANK(P9,P$3:P$38,0) -> 27 | AB9: =RANK(Q9,Q$3:Q$38,0) -> 20 | AC9: =RANK(R9,R$3:R$38,0) -> 21 | AD9: =RANK(S9,S$3:S$38,0) -> 20 | AF9: =RANK(U9,U$3:U$38,0) -> 18
A10: ='FM-1'!A10 -> 8 | B10: ='FM-1'!B10 -> 7TH | C10: ='FM-1'!D10 -> 1007 | D10: ='FM-1'!C10 -> 8 | E10: ='FM-1'!E10 -> Ali8 | F10: ='FM-1'!F10 -> Khan 8 | G10: ='FM-1'!G10 -> 3005326994 | H10: ='FM-1'!H10 -> 0 | I10: ='FM-1'!I10 -> APS Hazro | J10: ='Marks Input'!F11 -> ANNUAL EXAM 2024 | K10: ='Marks Input'!G11 -> 69 | L10: ='Marks Input'!H11 -> 33 | M10: ='Marks Input'!N11 -> 60 | N10: ='Marks Input'!L11 -> 48 | O10: ='Marks Input'!I11 -> 50 | P10: ='Marks Input'!J11 -> 83 | Q10: ='Marks Input'!M11 -> 73 | R10: ='Marks Input'!K11 -> 93 | S10: ='Marks Input'!M11 -> 73 | T10: 11 | U10: ='Marks Input'!P11 -> 548 | V10: =RANK(K10,K$3:K$38,0) -> 6 | W10: =RANK(L10,L$3:L$38,0) -> 19 | X10: =RANK(M10,M$3:M$38,0) -> 1 | Y10: =RANK(N10,N$3:N$38,0) -> 26 | Z10: =RANK(O10,O$3:O$38,0) -> 12 | AA10: =RANK(P10,P$3:P$38,0) -> 13 | AB10: =RANK(Q10,Q$3:Q$38,0) -> 7 | AC10: =RANK(R10,R$3:R$38,0) -> 4 | AD10: =RANK(S10,S$3:S$38,0) -> 7 | AF10: =RANK(U10,U$3:U$38,0) -> 10
A11: ='FM-1'!A11 -> 9 | B11: ='FM-1'!B11 -> 7TH | C11: ='FM-1'!D11 -> 1008 | D11: ='FM-1'!C11 -> 9 | E11: ='FM-1'!E11 -> Ali9 | F11: ='FM-1'!F11 -> Khan 9 | G11: ='FM-1'!G11 -> 3005327035 | H11: ='FM-1'!H11 -> 0 | I11: ='FM-1'!I11 -> APS Hazro | J11: ='Marks Input'!F12 -> ANNUAL EXAM 2024 | K11: ='Marks Input'!G12 -> 65 | L11: ='Marks Input'!H12 -> 33 | M11: ='Marks Input'!N12 -> 20 | N11: ='Marks Input'!L12 -> 42 | O11: ='Marks Input'!I12 -> 44 | P11: ='Marks Input'!J12 -> 40 | Q11: ='Marks Input'!M12 -> 43 | R11: ='Marks Input'!K12 -> 73 | S11: ='Marks Input'!M12 -> 43 | T11: 11 | U11: ='Marks Input'!P12 -> 375 | V11: =RANK(K11,K$3:K$38,0) -> 15 | W11: =RANK(L11,L$3:L$38,0) -> 19 | X11: =RANK(M11,M$3:M$38,0) -> 29 | Y11: =RANK(N11,N$3:N$38,0) -> 30 | Z11: =RANK(O11,O$3:O$38,0) -> 18 | AA11: =RANK(P11,P$3:P$38,0) -> 30 | AB11: =RANK(Q11,Q$3:Q$38,0) -> 28 | AC11: =RANK(R11,R$3:R$38,0) -> 23 | AD11: =RANK(S11,S$3:S$38,0) -> 28 | AF11: =RANK(U11,U$3:U$38,0) -> 29
A12: ='FM-1'!A12 -> 10 | B12: ='FM-1'!B12 -> 7TH | C12: ='FM-1'!D12 -> 1009 | D12: ='FM-1'!C12 -> 10 | E12: ='FM-1'!E12 -> Ali10 | F12: ='FM-1'!F12 -> Khan 10 | G12: ='FM-1'!G12 -> 3005327076 | H12: ='FM-1'!H12 -> 0 | I12: ='FM-1'!I12 -> APS Hazro | J12: ='Marks Input'!F13 -> ANNUAL EXAM 2024 | K12: ='Marks Input'!G13 -> 49 | L12: ='Marks Input'!H13 -> 33 | M12: ='Marks Input'!N13 -> 19 | N12: ='Marks Input'!L13 -> 40 | O12: ='Marks Input'!I13 -> 40 | P12: ='Marks Input'!J13 -> 35 | Q12: ='Marks Input'!M13 -> 37 | R12: ='Marks Input'!K13 -> 60 | S12: ='Marks Input'!M13 -> 37 | T12: 11 | U12: ='Marks Input'!P13 -> 328 | V12: =RANK(K12,K$3:K$38,0) -> 31 | W12: =RANK(L12,L$3:L$38,0) -> 19 | X12: =RANK(M12,M$3:M$38,0) -> 32 | Y12: =RANK(N12,N$3:N$38,0) -> 31 | Z12: =RANK(O12,O$3:O$38,0) -> 19 | AA12: =RANK(P12,P$3:P$38,0) -> 32 | AB12: =RANK(Q12,Q$3:Q$38,0) -> 32 | AC12: =RANK(R12,R$3:R$38,0) -> 33 | AD12: =RANK(S12,S$3:S$38,0) -> 32 | AF12: =RANK(U12,U$3:U$38,0) -> 33
A13: ='FM-1'!A13 -> 11 | B13: ='FM-1'!B13 -> 7TH | C13: ='FM-1'!D13 -> 1010 | D13: ='FM-1'!C13 -> 11 | E13: ='FM-1'!E13 -> Ali11 | F13: ='FM-1'!F13 -> Khan 11 | G13: ='FM-1'!G13 -> 3005327117 | H13: ='FM-1'!H13 -> 0 | I13: ='FM-1'!I13 -> APS Hazro | J13: ='Marks Input'!F14 -> ANNUAL EXAM 2024 | K13: ='Marks Input'!G14 -> 40 | L13: ='Marks Input'!H14 -> 33 | M13: ='Marks Input'!N14 -> 20 | N13: ='Marks Input'!L14 -> 56 | O13: ='Marks Input'!I14 -> 40 | P13: ='Marks Input'!J14 -> 50 | Q13: ='Marks Input'!M14 -> 49 | R13: ='Marks Input'!K14 -> 62 | S13: ='Marks Input'!M14 -> 49 | T13: 11 | U13: ='Marks Input'!P14 -> 365 | V13: =RANK(K13,K$3:K$38,0) -> 34 | W13: =RANK(L13,L$3:L$38,0) -> 19 | X13: =RANK(M13,M$3:M$38,0) -> 29 | Y13: =RANK(N13,N$3:N$38,0) -> 17 | Z13: =RANK(O13,O$3:O$38,0) -> 19 | AA13: =RANK(P13,P$3:P$38,0) -> 27 | AB13: =RANK(Q13,Q$3:Q$38,0) -> 22 | AC13: =RANK(R13,R$3:R$38,0) -> 30 | AD13: =RANK(S13,S$3:S$38,0) -> 22 | AF13: =RANK(U13,U$3:U$38,0) -> 31
A14: ='FM-1'!A14 -> 12 | B14: ='FM-1'!B14 -> 7TH | C14: ='FM-1'!D14 -> 1011 | D14: ='FM-1'!C14 -> 12 | E14: ='FM-1'!E14 -> Ali12 | F14: ='FM-1'!F14 -> Khan 12 | G14: ='FM-1'!G14 -> 3005327158 | H14: ='FM-1'!H14 -> 0 | I14: ='FM-1'!I14 -> APS Hazro | J14: ='Marks Input'!F15 -> ANNUAL EXAM 2024 | K14: ='Marks Input'!G15 -> 54 | L14: ='Marks Input'!H15 -> 33 | M14: ='Marks Input'!N15 -> 18 | N14: ='Marks Input'!L15 -> 40 | O14: ='Marks Input'!I15 -> 36 | P14: ='Marks Input'!J15 -> 35 | Q14: ='Marks Input'!M15 -> 35 | R14: ='Marks Input'!K15 -> 57 | S14: ='Marks Input'!M15 -> 35 | T14: 11 | U14: ='Marks Input'!P15 -> 322 | V14: =RANK(K14,K$3:K$38,0) -> 28 | W14: =RANK(L14,L$3:L$38,0) -> 19 | X14: =RANK(M14,M$3:M$38,0) -> 34 | Y14: =RANK(N14,N$3:N$38,0) -> 31 | Z14: =RANK(O14,O$3:O$38,0) -> 27 | AA14: =RANK(P14,P$3:P$38,0) -> 32 | AB14: =RANK(Q14,Q$3:Q$38,0) -> 33 | AC14: =RANK(R14,R$3:R$38,0) -> 34 | AD14: =RANK(S14,S$3:S$38,0) -> 33 | AF14: =RANK(U14,U$3:U$38,0) -> 34
... A36: ='FM-1'!A36 -> 34 | B36: ='FM-1'!B36 -> 7TH | C36: ='FM-1'!D36 -> 1033 | D36: ='FM-1'!C36 -> 34 | E36: ='FM-1'!E36 -> Ali34 | F36: ='FM-1'!F36 -> Khan 34 | G36: ='FM-1'!G36 -> 3005328060 | H36: ='FM-1'!H36 -> 0 | I36: ='FM-1'!I36 -> APS Hazro | J36: ='Marks Input'!F37 -> ANNUAL EXAM 2024 | K36: ='Marks Input'!G37 -> 72 | L36: ='Marks Input'!H37 -> 58 | M36: ='Marks Input'!N37 -> 57 | N36: ='Marks Input'!L37 -> 90 | O36: ='Marks Input'!I37 -> 76 | P36: ='Marks Input'!J37 -> 95 | Q36: ='Marks Input'!M37 -> 61 | R36: ='Marks Input'!K37 -> 84 | S36: ='Marks Input'!M37 -> 61 | T36: 11 | U36: ='Marks Input'!P37 -> 633 | V36: =RANK(K36,K$3:K$38,0) -> 1 | W36: =RANK(L36,L$3:L$38,0) -> 8 | X36: =RANK(M36,M$3:M$38,0) -> 8 | Y36: =RANK(N36,N$3:N$38,0) -> 2 | Z36: =RANK(O36,O$3:O$38,0) -> 2 | AA36: =RANK(P36,P$3:P$38,0) -> 5 | AB36: =RANK(Q36,Q$3:Q$38,0) -> 10 | AC36: =RANK(R36,R$3:R$38,0) -> 6 | AD36: =RANK(S36,S$3:S$38,0) -> 10 | AF36: =RANK(U36,U$3:U$38,0) -> 4
J39: ='Marks Input'!F38 -> SUM | K39: =SUM(K3:K38) -> 2128 | L39: =SUM(L3:L38) -> 1471 | M39: =SUM(M3:M38) -> 1460 | N39: =SUM(N3:N38) -> 2077 | O39: =SUM(O3:O38) -> 1642 | P39: =SUM(P3:P38) -> 2415 | Q39: =SUM(Q3:Q38) -> 1965 | R39: =SUM(R3:R38) -> 2578 | ... U39: =SUM(U3:U38) -> 16771
J40: ='Marks Input'!F39 -> Student Count | K40: =COUNT(K3:K38) -> 34 | L40: =COUNT(L3:L38) -> 34 | M40: =COUNT(M3:M38) -> 34 | N40: =COUNT(N3:N38) -> 34 | O40: =COUNT(O3:O38) -> 34 | P40: =COUNT(P3:P38) -> 34 | Q40: =COUNT(Q3:Q38) -> 34 | R40: =COUNT(R3:R38) -> 34 | ... U40: =COUNT(U3:U38) -> 34
J41: ='Marks Input'!F40 -> Average | K41: =K39/K40 -> 62.588235 | L41: =L39/L40 -> 43.264706 | M41: =M39/M40 -> 42.941176 | N41: =N39/N40 -> 61.088235 | O41: =O39/O40 -> 48.294118 | P41: =P39/P40 -> 71.029412 | Q41: =Q39/Q40 -> 57.794118 | R41: =R39/R40 -> 75.823529 | ... U41: =U39/U40 -> 493.26471

Sheet Students Attendance
A1: STUDENT ATTENDANCE RECORD Clr | E1: SCHOOL: | F1: APS Hazro
A2: CLASS | B2: Month No. | D2: 1 | E2: Month: | F2: January | G2: Class: | H2: 7TH | J2: Section
B3: Roll No. | C3: Admission No. | D3: Name | E3: D.O.B | F3: FATHER NAME | G3: FATHER CNIC | H3: CONTACT # | I3: Home Address
J5: =H$2 -> 7TH
A6: =H$2 -> 7TH | B6: 1 | C6: 1000 | D6: Ali1 | E6: 36210 | F6: Khan 1 | H6: 3005326707 | J6: =H$2 -> 7TH
A7: =H$2 -> 7TH | B7: 2 | C7: 1001 | D7: Ali2 | E7: 32952 | F7: khan2 | H7: 3005326748 | J7: =H$2 -> 7TH
A8: =H$2 -> 7TH | B8: 3 | C8: 1002 | D8: Ali3 | E8: 34731 | F8: khan3 | H8: 3005326789 | J8: =H$2 -> 7TH
A9: =H$2 -> 7TH | B9: 4 | C9: 1003 | D9: Ali4 | E9: 36210 | F9: Khan 4 | H9: 3005326830 | J9: =H$2 -> 7TH
A10: =H$2 -> 7TH | B10: 5 | C10: 1004 | D10: Ali5 | E10: 32952 | F10: Khan 5 | H10: 3005326871 | J10: =H$2 -> 7TH
A11: =H$2 -> 7TH | B11: 6 | C11: 1005 | D11: Ali6 | E11: 34731 | F11: Khan 6 | H11: 3005326912 | J11: =H$2 -> 7TH
A12: =H$2 -> 7TH | B12: 7 | C12: 1006 | D12: Ali7 | E12: 35783 | F12: Khan 7 | H12: 3005326953 | J12: =H$2 -> 7TH
A13: =H$2 -> 7TH | B13: 8 | C13: 1007 | D13: Ali8 | E13: 36210 | F13: Khan 8 | H13: 3005326994 | J13: =H$2 -> 7TH
A14: =H$2 -> 7TH | B14: 9 | C14: 1008 | D14: Ali9 | E14: 32952 | F14: Khan 9 | H14: 3005327035 | J14: =H$2 -> 7TH
A15: =H$2 -> 7TH | B15: 10 | C15: 1009 | D15: Ali10 | E15: 34731 | F15: Khan 10 | H15: 3005327076 | J15: =H$2 -> 7TH
A16: =H$2 -> 7TH | B16: 11 | C16: 1010 | D16: Ali11 | E16: 36210 | F16: Khan 11 | H16: 3005327117 | J16: =H$2 -> 7TH
A17: =H$2 -> 7TH | B17: 12 | C17: 1011 | D17: Ali12 | E17: 32952 | F17: Khan 12 | H17: 3005327158 | J17: =H$2 -> 7TH
... A39: =H$2 -> 7TH | B39: 34 | C39: 1033 | D39: Ali34 | E39: 34731 | F39: Khan 34 | H39: 3005328060 | J39: =H$2 -> 7TH
J40: All
J41: P
J42: A
J43: CL
J44: ML
J45: L
J46: E

Sheet Sheet6
B3: 1 | C3: 2 | D3: 3 | E3: 4 | F3: 5 | G3: 6 | H3: 7 | I3: 8 | J3: 9 | K3: 10 | L3: 11 | M3: 12 | O3: 1
A4: 1 | B4: 45352 | C4: 45384 | D4: 45413 | E4: 45444 | F4: 45475 | G4: 45505 | H4: 45536 | I4: 45566 | J4: 45597 | K4: 45627 | L4: 45658 | M4: 45689 | O4: Monday
A5: 2 | B5: 45353 | C5: 45385 | D5: 45414 | E5: 45445 | F5: 45476 | G5: 45506 | H5: 45538 | I5: 45567 | J5: 45598 | K5: 45629 | L5: 45659 | M5: 45690 | O5: Tuesday
A6: 3 | B6: 45354 | C6: 45386 | D6: 45415 | E6: 45447 | F6: 45477 | G6: 45507 | H6: 45539 | I6: 45568 | J6: 45599 | K6: 45630 | L6: 45660 | M6: 45692 | O6: Wednesday
A7: 4 | B7: 45356 | C7: 45387 | D7: 45416 | E7: 45448 | F7: 45478 | G7: 45508 | H7: 45540 | I7: 45569 | J7: 45601 | K7: 45631 | L7: 45661 | M7: 45693 | O7: Thursday
A8: 5 | B8: 45357 | C8: 45388 | D8: 45417 | E8: 45449 | F8: 45479 | G8: 45510 | H8: 45541 | I8: 45570 | J8: 45602 | K8: 45632 | L8: 45662 | M8: 45694 | O8: Friday
A9: 6 | B9: 45358 | C9: 45389 | D9: 45419 | E9: 45450 | F9: 45480 | G9: 45511 | H9: 45542 | I9: 45571 | J9: 45603 | K9: 45633 | L9: 45664 | M9: 45695 | O9: Saturday
A10: 7 | B10: 45359 | C10: 45391 | D10: 45420 | E10: 45451 | F10: 45482 | G10: 45512 | H10: 45543 | I10: 45573 | J10: 45604 | K10: 45634 | L10: 45665 | M10: 45696 | O10: Sunday
A11: 8 | B11: 45360 | C11: 45392 | D11: 45421 | E11: 45452 | F11: 45483 | G11: 45513 | H11: 45545 | I11: 45574 | J11: 45605 | K11: 45636 | L11: 45666 | M11: 45697 | O11: Monday
A12: 9 | B12: 45361 | C12: 45393 | D12: 45422 | E12: 45454 | F12: 45484 | G12: 45514 | H12: 45546 | I12: 45575 | J12: 45606 | K12: 45637 | L12: 45667 | M12: 45699 | O12: Tuesday
A13: 10 | B13: 45363 | C13: 45394 | D13: 45423 | E13: 45455 | F13: 45485 | G13: 45515 | H13: 45547 | I13: 45576 | J13: 45608 | K13: 45638 | L13: 45668 | M13: 45700 | O13: Wednesday
A14: 11 | B14: 45364 | C14: 45395 | D14: 45424 | E14: 45456 | F14: 45486 | G14: 45517 | H14: 45548 | I14: 45577 | J14: 45609 | K14: 45639 | L14: 45669 | M14: 45701 | O14: Thursday
A15: 12 | B15: 45365 | C15: 45396 | D15: 45426 | E15: 45457 | F15: 45487 | G15: 45518 | H15: 45549 | I15: 45578 | J15: 45610 | K15: 45640 | L15: 45671 | M15: 45702 | O15: Friday
... A27: 24 | B27: 45379 | C27: 45410 | D27: 45440 | E27: 45471 | F27: 45501 | G27: 45532 | H27: 45563 | I27: 45592 | J27: 45624 | K27: 45654 | L27: 45685 | M27: 45716 | O27: Wednesday
A28: 25 | B28: 45380 | C28: 45412 | D28: 45441 | E28: 45472 | F28: 45503 | G28: 45533 | H28: 45564 | I28: 45594 | J28: 45625 | K28: 45655 | L28: 45686 | M28: #N/A | O28: Thursday
A29: 26 | B29: 45381 | C29: #N/A | D29: 45442 | E29: 45473 | F29: 45504 | G29: 45534 | I29: 45595 | J29: 45626 | K29: 45657 | L29: 45687 | M29: #N/A | O29: Friday
A30: 27 | B30: 45382 | C30: #N/A | D30: 45443 | E30: #N/A | F30: #N/A | G30: 45535 | I30: 45596 | J30: #N/A | K30: #N/A | L30: 45688 | M30: #N/A | O30: Saturday
